[2022-05-19 19:02:07,701] {processor.py:163} INFO - Started process (PID=242) to work on /opt/airflow/dags/data_ingestion_gcs_dag.py
[2022-05-19 19:02:07,711] {processor.py:642} INFO - Processing file /opt/airflow/dags/data_ingestion_gcs_dag.py for tasks to queue
[2022-05-19 19:02:07,716] {logging_mixin.py:109} INFO - [2022-05-19 19:02:07,716] {dagbag.py:500} INFO - Filling up the DagBag from /opt/airflow/dags/data_ingestion_gcs_dag.py
[2022-05-19 19:02:07,733] {logging_mixin.py:109} INFO - [2022-05-19 19:02:07,728] {dagbag.py:334} ERROR - Failed to import: /opt/airflow/dags/data_ingestion_gcs_dag.py
Traceback (most recent call last):
  File "/home/airflow/.local/lib/python3.7/site-packages/airflow/models/dagbag.py", line 331, in _load_modules_from_file
    loader.exec_module(new_module)
  File "<frozen importlib._bootstrap_external>", line 724, in exec_module
  File "<frozen importlib._bootstrap_external>", line 860, in get_code
  File "<frozen importlib._bootstrap_external>", line 791, in source_to_code
  File "<frozen importlib._bootstrap>", line 219, in _call_with_frames_removed
  File "/opt/airflow/dags/data_ingestion_gcs_dag.py", line 1
    import os
    ^
IndentationError: unexpected indent
[2022-05-19 19:02:07,768] {processor.py:656} WARNING - No viable dags retrieved from /opt/airflow/dags/data_ingestion_gcs_dag.py
[2022-05-19 19:02:07,802] {processor.py:171} INFO - Processing /opt/airflow/dags/data_ingestion_gcs_dag.py took 0.114 seconds
[2022-05-19 19:02:38,177] {processor.py:163} INFO - Started process (PID=255) to work on /opt/airflow/dags/data_ingestion_gcs_dag.py
[2022-05-19 19:02:38,184] {processor.py:642} INFO - Processing file /opt/airflow/dags/data_ingestion_gcs_dag.py for tasks to queue
[2022-05-19 19:02:38,188] {logging_mixin.py:109} INFO - [2022-05-19 19:02:38,188] {dagbag.py:500} INFO - Filling up the DagBag from /opt/airflow/dags/data_ingestion_gcs_dag.py
[2022-05-19 19:02:38,212] {logging_mixin.py:109} INFO - [2022-05-19 19:02:38,203] {dagbag.py:334} ERROR - Failed to import: /opt/airflow/dags/data_ingestion_gcs_dag.py
Traceback (most recent call last):
  File "/home/airflow/.local/lib/python3.7/site-packages/airflow/models/dagbag.py", line 331, in _load_modules_from_file
    loader.exec_module(new_module)
  File "<frozen importlib._bootstrap_external>", line 724, in exec_module
  File "<frozen importlib._bootstrap_external>", line 860, in get_code
  File "<frozen importlib._bootstrap_external>", line 791, in source_to_code
  File "<frozen importlib._bootstrap>", line 219, in _call_with_frames_removed
  File "/opt/airflow/dags/data_ingestion_gcs_dag.py", line 1
    import os
    ^
IndentationError: unexpected indent
[2022-05-19 19:02:38,277] {processor.py:656} WARNING - No viable dags retrieved from /opt/airflow/dags/data_ingestion_gcs_dag.py
[2022-05-19 19:02:38,320] {processor.py:171} INFO - Processing /opt/airflow/dags/data_ingestion_gcs_dag.py took 0.156 seconds
[2022-05-19 19:03:08,812] {processor.py:163} INFO - Started process (PID=271) to work on /opt/airflow/dags/data_ingestion_gcs_dag.py
[2022-05-19 19:03:08,818] {processor.py:642} INFO - Processing file /opt/airflow/dags/data_ingestion_gcs_dag.py for tasks to queue
[2022-05-19 19:03:08,821] {logging_mixin.py:109} INFO - [2022-05-19 19:03:08,821] {dagbag.py:500} INFO - Filling up the DagBag from /opt/airflow/dags/data_ingestion_gcs_dag.py
[2022-05-19 19:03:08,840] {logging_mixin.py:109} INFO - [2022-05-19 19:03:08,836] {dagbag.py:334} ERROR - Failed to import: /opt/airflow/dags/data_ingestion_gcs_dag.py
Traceback (most recent call last):
  File "/home/airflow/.local/lib/python3.7/site-packages/airflow/models/dagbag.py", line 331, in _load_modules_from_file
    loader.exec_module(new_module)
  File "<frozen importlib._bootstrap_external>", line 724, in exec_module
  File "<frozen importlib._bootstrap_external>", line 860, in get_code
  File "<frozen importlib._bootstrap_external>", line 791, in source_to_code
  File "<frozen importlib._bootstrap>", line 219, in _call_with_frames_removed
  File "/opt/airflow/dags/data_ingestion_gcs_dag.py", line 1
    import os
    ^
IndentationError: unexpected indent
[2022-05-19 19:03:08,872] {processor.py:656} WARNING - No viable dags retrieved from /opt/airflow/dags/data_ingestion_gcs_dag.py
[2022-05-19 19:03:08,892] {processor.py:171} INFO - Processing /opt/airflow/dags/data_ingestion_gcs_dag.py took 0.087 seconds
[2022-05-19 19:03:39,413] {processor.py:163} INFO - Started process (PID=287) to work on /opt/airflow/dags/data_ingestion_gcs_dag.py
[2022-05-19 19:03:39,417] {processor.py:642} INFO - Processing file /opt/airflow/dags/data_ingestion_gcs_dag.py for tasks to queue
[2022-05-19 19:03:39,420] {logging_mixin.py:109} INFO - [2022-05-19 19:03:39,420] {dagbag.py:500} INFO - Filling up the DagBag from /opt/airflow/dags/data_ingestion_gcs_dag.py
[2022-05-19 19:03:39,443] {logging_mixin.py:109} INFO - [2022-05-19 19:03:39,439] {dagbag.py:334} ERROR - Failed to import: /opt/airflow/dags/data_ingestion_gcs_dag.py
Traceback (most recent call last):
  File "/home/airflow/.local/lib/python3.7/site-packages/airflow/models/dagbag.py", line 331, in _load_modules_from_file
    loader.exec_module(new_module)
  File "<frozen importlib._bootstrap_external>", line 724, in exec_module
  File "<frozen importlib._bootstrap_external>", line 860, in get_code
  File "<frozen importlib._bootstrap_external>", line 791, in source_to_code
  File "<frozen importlib._bootstrap>", line 219, in _call_with_frames_removed
  File "/opt/airflow/dags/data_ingestion_gcs_dag.py", line 1
    import os
    ^
IndentationError: unexpected indent
[2022-05-19 19:03:39,481] {processor.py:656} WARNING - No viable dags retrieved from /opt/airflow/dags/data_ingestion_gcs_dag.py
[2022-05-19 19:03:39,501] {processor.py:171} INFO - Processing /opt/airflow/dags/data_ingestion_gcs_dag.py took 0.098 seconds
[2022-05-19 19:04:10,085] {processor.py:163} INFO - Started process (PID=303) to work on /opt/airflow/dags/data_ingestion_gcs_dag.py
[2022-05-19 19:04:10,088] {processor.py:642} INFO - Processing file /opt/airflow/dags/data_ingestion_gcs_dag.py for tasks to queue
[2022-05-19 19:04:10,091] {logging_mixin.py:109} INFO - [2022-05-19 19:04:10,091] {dagbag.py:500} INFO - Filling up the DagBag from /opt/airflow/dags/data_ingestion_gcs_dag.py
[2022-05-19 19:04:10,106] {logging_mixin.py:109} INFO - [2022-05-19 19:04:10,103] {dagbag.py:334} ERROR - Failed to import: /opt/airflow/dags/data_ingestion_gcs_dag.py
Traceback (most recent call last):
  File "/home/airflow/.local/lib/python3.7/site-packages/airflow/models/dagbag.py", line 331, in _load_modules_from_file
    loader.exec_module(new_module)
  File "<frozen importlib._bootstrap_external>", line 724, in exec_module
  File "<frozen importlib._bootstrap_external>", line 860, in get_code
  File "<frozen importlib._bootstrap_external>", line 791, in source_to_code
  File "<frozen importlib._bootstrap>", line 219, in _call_with_frames_removed
  File "/opt/airflow/dags/data_ingestion_gcs_dag.py", line 1
    import os
    ^
IndentationError: unexpected indent
[2022-05-19 19:04:10,135] {processor.py:656} WARNING - No viable dags retrieved from /opt/airflow/dags/data_ingestion_gcs_dag.py
[2022-05-19 19:04:10,158] {processor.py:171} INFO - Processing /opt/airflow/dags/data_ingestion_gcs_dag.py took 0.081 seconds
[2022-05-19 19:04:40,761] {processor.py:163} INFO - Started process (PID=319) to work on /opt/airflow/dags/data_ingestion_gcs_dag.py
[2022-05-19 19:04:40,764] {processor.py:642} INFO - Processing file /opt/airflow/dags/data_ingestion_gcs_dag.py for tasks to queue
[2022-05-19 19:04:40,767] {logging_mixin.py:109} INFO - [2022-05-19 19:04:40,766] {dagbag.py:500} INFO - Filling up the DagBag from /opt/airflow/dags/data_ingestion_gcs_dag.py
[2022-05-19 19:04:40,780] {logging_mixin.py:109} INFO - [2022-05-19 19:04:40,777] {dagbag.py:334} ERROR - Failed to import: /opt/airflow/dags/data_ingestion_gcs_dag.py
Traceback (most recent call last):
  File "/home/airflow/.local/lib/python3.7/site-packages/airflow/models/dagbag.py", line 331, in _load_modules_from_file
    loader.exec_module(new_module)
  File "<frozen importlib._bootstrap_external>", line 724, in exec_module
  File "<frozen importlib._bootstrap_external>", line 860, in get_code
  File "<frozen importlib._bootstrap_external>", line 791, in source_to_code
  File "<frozen importlib._bootstrap>", line 219, in _call_with_frames_removed
  File "/opt/airflow/dags/data_ingestion_gcs_dag.py", line 1
    import os
    ^
IndentationError: unexpected indent
[2022-05-19 19:04:40,815] {processor.py:656} WARNING - No viable dags retrieved from /opt/airflow/dags/data_ingestion_gcs_dag.py
[2022-05-19 19:04:40,835] {processor.py:171} INFO - Processing /opt/airflow/dags/data_ingestion_gcs_dag.py took 0.080 seconds
[2022-05-19 19:05:11,329] {processor.py:163} INFO - Started process (PID=335) to work on /opt/airflow/dags/data_ingestion_gcs_dag.py
[2022-05-19 19:05:11,333] {processor.py:642} INFO - Processing file /opt/airflow/dags/data_ingestion_gcs_dag.py for tasks to queue
[2022-05-19 19:05:11,336] {logging_mixin.py:109} INFO - [2022-05-19 19:05:11,335] {dagbag.py:500} INFO - Filling up the DagBag from /opt/airflow/dags/data_ingestion_gcs_dag.py
[2022-05-19 19:05:11,349] {logging_mixin.py:109} INFO - [2022-05-19 19:05:11,346] {dagbag.py:334} ERROR - Failed to import: /opt/airflow/dags/data_ingestion_gcs_dag.py
Traceback (most recent call last):
  File "/home/airflow/.local/lib/python3.7/site-packages/airflow/models/dagbag.py", line 331, in _load_modules_from_file
    loader.exec_module(new_module)
  File "<frozen importlib._bootstrap_external>", line 724, in exec_module
  File "<frozen importlib._bootstrap_external>", line 860, in get_code
  File "<frozen importlib._bootstrap_external>", line 791, in source_to_code
  File "<frozen importlib._bootstrap>", line 219, in _call_with_frames_removed
  File "/opt/airflow/dags/data_ingestion_gcs_dag.py", line 1
    import os
    ^
IndentationError: unexpected indent
[2022-05-19 19:05:11,377] {processor.py:656} WARNING - No viable dags retrieved from /opt/airflow/dags/data_ingestion_gcs_dag.py
[2022-05-19 19:05:11,396] {processor.py:171} INFO - Processing /opt/airflow/dags/data_ingestion_gcs_dag.py took 0.074 seconds
[2022-05-19 19:05:41,946] {processor.py:163} INFO - Started process (PID=351) to work on /opt/airflow/dags/data_ingestion_gcs_dag.py
[2022-05-19 19:05:41,950] {processor.py:642} INFO - Processing file /opt/airflow/dags/data_ingestion_gcs_dag.py for tasks to queue
[2022-05-19 19:05:41,952] {logging_mixin.py:109} INFO - [2022-05-19 19:05:41,952] {dagbag.py:500} INFO - Filling up the DagBag from /opt/airflow/dags/data_ingestion_gcs_dag.py
[2022-05-19 19:05:41,966] {logging_mixin.py:109} INFO - [2022-05-19 19:05:41,962] {dagbag.py:334} ERROR - Failed to import: /opt/airflow/dags/data_ingestion_gcs_dag.py
Traceback (most recent call last):
  File "/home/airflow/.local/lib/python3.7/site-packages/airflow/models/dagbag.py", line 331, in _load_modules_from_file
    loader.exec_module(new_module)
  File "<frozen importlib._bootstrap_external>", line 724, in exec_module
  File "<frozen importlib._bootstrap_external>", line 860, in get_code
  File "<frozen importlib._bootstrap_external>", line 791, in source_to_code
  File "<frozen importlib._bootstrap>", line 219, in _call_with_frames_removed
  File "/opt/airflow/dags/data_ingestion_gcs_dag.py", line 1
    import os
    ^
IndentationError: unexpected indent
[2022-05-19 19:05:41,994] {processor.py:656} WARNING - No viable dags retrieved from /opt/airflow/dags/data_ingestion_gcs_dag.py
[2022-05-19 19:05:42,023] {processor.py:171} INFO - Processing /opt/airflow/dags/data_ingestion_gcs_dag.py took 0.084 seconds
[2022-05-19 19:06:12,637] {processor.py:163} INFO - Started process (PID=367) to work on /opt/airflow/dags/data_ingestion_gcs_dag.py
[2022-05-19 19:06:12,641] {processor.py:642} INFO - Processing file /opt/airflow/dags/data_ingestion_gcs_dag.py for tasks to queue
[2022-05-19 19:06:12,643] {logging_mixin.py:109} INFO - [2022-05-19 19:06:12,643] {dagbag.py:500} INFO - Filling up the DagBag from /opt/airflow/dags/data_ingestion_gcs_dag.py
[2022-05-19 19:06:12,656] {logging_mixin.py:109} INFO - [2022-05-19 19:06:12,653] {dagbag.py:334} ERROR - Failed to import: /opt/airflow/dags/data_ingestion_gcs_dag.py
Traceback (most recent call last):
  File "/home/airflow/.local/lib/python3.7/site-packages/airflow/models/dagbag.py", line 331, in _load_modules_from_file
    loader.exec_module(new_module)
  File "<frozen importlib._bootstrap_external>", line 724, in exec_module
  File "<frozen importlib._bootstrap_external>", line 860, in get_code
  File "<frozen importlib._bootstrap_external>", line 791, in source_to_code
  File "<frozen importlib._bootstrap>", line 219, in _call_with_frames_removed
  File "/opt/airflow/dags/data_ingestion_gcs_dag.py", line 1
    import os
    ^
IndentationError: unexpected indent
[2022-05-19 19:06:12,685] {processor.py:656} WARNING - No viable dags retrieved from /opt/airflow/dags/data_ingestion_gcs_dag.py
[2022-05-19 19:06:12,707] {processor.py:171} INFO - Processing /opt/airflow/dags/data_ingestion_gcs_dag.py took 0.075 seconds
[2022-05-19 19:06:43,144] {processor.py:163} INFO - Started process (PID=383) to work on /opt/airflow/dags/data_ingestion_gcs_dag.py
[2022-05-19 19:06:43,147] {processor.py:642} INFO - Processing file /opt/airflow/dags/data_ingestion_gcs_dag.py for tasks to queue
[2022-05-19 19:06:43,150] {logging_mixin.py:109} INFO - [2022-05-19 19:06:43,150] {dagbag.py:500} INFO - Filling up the DagBag from /opt/airflow/dags/data_ingestion_gcs_dag.py
[2022-05-19 19:06:43,163] {logging_mixin.py:109} INFO - [2022-05-19 19:06:43,160] {dagbag.py:334} ERROR - Failed to import: /opt/airflow/dags/data_ingestion_gcs_dag.py
Traceback (most recent call last):
  File "/home/airflow/.local/lib/python3.7/site-packages/airflow/models/dagbag.py", line 331, in _load_modules_from_file
    loader.exec_module(new_module)
  File "<frozen importlib._bootstrap_external>", line 724, in exec_module
  File "<frozen importlib._bootstrap_external>", line 860, in get_code
  File "<frozen importlib._bootstrap_external>", line 791, in source_to_code
  File "<frozen importlib._bootstrap>", line 219, in _call_with_frames_removed
  File "/opt/airflow/dags/data_ingestion_gcs_dag.py", line 1
    import os
    ^
IndentationError: unexpected indent
[2022-05-19 19:06:43,191] {processor.py:656} WARNING - No viable dags retrieved from /opt/airflow/dags/data_ingestion_gcs_dag.py
[2022-05-19 19:06:43,212] {processor.py:171} INFO - Processing /opt/airflow/dags/data_ingestion_gcs_dag.py took 0.077 seconds
[2022-05-19 19:07:13,767] {processor.py:163} INFO - Started process (PID=399) to work on /opt/airflow/dags/data_ingestion_gcs_dag.py
[2022-05-19 19:07:13,771] {processor.py:642} INFO - Processing file /opt/airflow/dags/data_ingestion_gcs_dag.py for tasks to queue
[2022-05-19 19:07:13,773] {logging_mixin.py:109} INFO - [2022-05-19 19:07:13,772] {dagbag.py:500} INFO - Filling up the DagBag from /opt/airflow/dags/data_ingestion_gcs_dag.py
[2022-05-19 19:07:13,785] {logging_mixin.py:109} INFO - [2022-05-19 19:07:13,782] {dagbag.py:334} ERROR - Failed to import: /opt/airflow/dags/data_ingestion_gcs_dag.py
Traceback (most recent call last):
  File "/home/airflow/.local/lib/python3.7/site-packages/airflow/models/dagbag.py", line 331, in _load_modules_from_file
    loader.exec_module(new_module)
  File "<frozen importlib._bootstrap_external>", line 724, in exec_module
  File "<frozen importlib._bootstrap_external>", line 860, in get_code
  File "<frozen importlib._bootstrap_external>", line 791, in source_to_code
  File "<frozen importlib._bootstrap>", line 219, in _call_with_frames_removed
  File "/opt/airflow/dags/data_ingestion_gcs_dag.py", line 1
    import os
    ^
IndentationError: unexpected indent
[2022-05-19 19:07:13,812] {processor.py:656} WARNING - No viable dags retrieved from /opt/airflow/dags/data_ingestion_gcs_dag.py
[2022-05-19 19:07:13,831] {processor.py:171} INFO - Processing /opt/airflow/dags/data_ingestion_gcs_dag.py took 0.070 seconds
[2022-05-19 19:07:44,389] {processor.py:163} INFO - Started process (PID=415) to work on /opt/airflow/dags/data_ingestion_gcs_dag.py
[2022-05-19 19:07:44,393] {processor.py:642} INFO - Processing file /opt/airflow/dags/data_ingestion_gcs_dag.py for tasks to queue
[2022-05-19 19:07:44,395] {logging_mixin.py:109} INFO - [2022-05-19 19:07:44,395] {dagbag.py:500} INFO - Filling up the DagBag from /opt/airflow/dags/data_ingestion_gcs_dag.py
[2022-05-19 19:07:44,407] {logging_mixin.py:109} INFO - [2022-05-19 19:07:44,404] {dagbag.py:334} ERROR - Failed to import: /opt/airflow/dags/data_ingestion_gcs_dag.py
Traceback (most recent call last):
  File "/home/airflow/.local/lib/python3.7/site-packages/airflow/models/dagbag.py", line 331, in _load_modules_from_file
    loader.exec_module(new_module)
  File "<frozen importlib._bootstrap_external>", line 724, in exec_module
  File "<frozen importlib._bootstrap_external>", line 860, in get_code
  File "<frozen importlib._bootstrap_external>", line 791, in source_to_code
  File "<frozen importlib._bootstrap>", line 219, in _call_with_frames_removed
  File "/opt/airflow/dags/data_ingestion_gcs_dag.py", line 1
    import os
    ^
IndentationError: unexpected indent
[2022-05-19 19:07:44,433] {processor.py:656} WARNING - No viable dags retrieved from /opt/airflow/dags/data_ingestion_gcs_dag.py
[2022-05-19 19:07:44,451] {processor.py:171} INFO - Processing /opt/airflow/dags/data_ingestion_gcs_dag.py took 0.069 seconds
[2022-05-19 19:08:14,853] {processor.py:163} INFO - Started process (PID=431) to work on /opt/airflow/dags/data_ingestion_gcs_dag.py
[2022-05-19 19:08:14,858] {processor.py:642} INFO - Processing file /opt/airflow/dags/data_ingestion_gcs_dag.py for tasks to queue
[2022-05-19 19:08:14,860] {logging_mixin.py:109} INFO - [2022-05-19 19:08:14,860] {dagbag.py:500} INFO - Filling up the DagBag from /opt/airflow/dags/data_ingestion_gcs_dag.py
[2022-05-19 19:08:14,879] {logging_mixin.py:109} INFO - [2022-05-19 19:08:14,875] {dagbag.py:334} ERROR - Failed to import: /opt/airflow/dags/data_ingestion_gcs_dag.py
Traceback (most recent call last):
  File "/home/airflow/.local/lib/python3.7/site-packages/airflow/models/dagbag.py", line 331, in _load_modules_from_file
    loader.exec_module(new_module)
  File "<frozen importlib._bootstrap_external>", line 724, in exec_module
  File "<frozen importlib._bootstrap_external>", line 860, in get_code
  File "<frozen importlib._bootstrap_external>", line 791, in source_to_code
  File "<frozen importlib._bootstrap>", line 219, in _call_with_frames_removed
  File "/opt/airflow/dags/data_ingestion_gcs_dag.py", line 1
    import os
    ^
IndentationError: unexpected indent
[2022-05-19 19:08:14,914] {processor.py:656} WARNING - No viable dags retrieved from /opt/airflow/dags/data_ingestion_gcs_dag.py
[2022-05-19 19:08:14,933] {processor.py:171} INFO - Processing /opt/airflow/dags/data_ingestion_gcs_dag.py took 0.090 seconds
[2022-05-19 19:08:45,574] {processor.py:163} INFO - Started process (PID=439) to work on /opt/airflow/dags/data_ingestion_gcs_dag.py
[2022-05-19 19:08:45,578] {processor.py:642} INFO - Processing file /opt/airflow/dags/data_ingestion_gcs_dag.py for tasks to queue
[2022-05-19 19:08:45,581] {logging_mixin.py:109} INFO - [2022-05-19 19:08:45,580] {dagbag.py:500} INFO - Filling up the DagBag from /opt/airflow/dags/data_ingestion_gcs_dag.py
[2022-05-19 19:08:45,609] {logging_mixin.py:109} INFO - [2022-05-19 19:08:45,605] {dagbag.py:334} ERROR - Failed to import: /opt/airflow/dags/data_ingestion_gcs_dag.py
Traceback (most recent call last):
  File "/home/airflow/.local/lib/python3.7/site-packages/airflow/models/dagbag.py", line 331, in _load_modules_from_file
    loader.exec_module(new_module)
  File "<frozen importlib._bootstrap_external>", line 724, in exec_module
  File "<frozen importlib._bootstrap_external>", line 860, in get_code
  File "<frozen importlib._bootstrap_external>", line 791, in source_to_code
  File "<frozen importlib._bootstrap>", line 219, in _call_with_frames_removed
  File "/opt/airflow/dags/data_ingestion_gcs_dag.py", line 1
    import os
    ^
IndentationError: unexpected indent
[2022-05-19 19:08:45,651] {processor.py:656} WARNING - No viable dags retrieved from /opt/airflow/dags/data_ingestion_gcs_dag.py
[2022-05-19 19:08:45,680] {processor.py:171} INFO - Processing /opt/airflow/dags/data_ingestion_gcs_dag.py took 0.118 seconds
[2022-05-19 19:09:16,240] {processor.py:163} INFO - Started process (PID=453) to work on /opt/airflow/dags/data_ingestion_gcs_dag.py
[2022-05-19 19:09:16,243] {processor.py:642} INFO - Processing file /opt/airflow/dags/data_ingestion_gcs_dag.py for tasks to queue
[2022-05-19 19:09:16,246] {logging_mixin.py:109} INFO - [2022-05-19 19:09:16,245] {dagbag.py:500} INFO - Filling up the DagBag from /opt/airflow/dags/data_ingestion_gcs_dag.py
[2022-05-19 19:09:16,262] {logging_mixin.py:109} INFO - [2022-05-19 19:09:16,258] {dagbag.py:334} ERROR - Failed to import: /opt/airflow/dags/data_ingestion_gcs_dag.py
Traceback (most recent call last):
  File "/home/airflow/.local/lib/python3.7/site-packages/airflow/models/dagbag.py", line 331, in _load_modules_from_file
    loader.exec_module(new_module)
  File "<frozen importlib._bootstrap_external>", line 724, in exec_module
  File "<frozen importlib._bootstrap_external>", line 860, in get_code
  File "<frozen importlib._bootstrap_external>", line 791, in source_to_code
  File "<frozen importlib._bootstrap>", line 219, in _call_with_frames_removed
  File "/opt/airflow/dags/data_ingestion_gcs_dag.py", line 1
    import os
    ^
IndentationError: unexpected indent
[2022-05-19 19:09:16,298] {processor.py:656} WARNING - No viable dags retrieved from /opt/airflow/dags/data_ingestion_gcs_dag.py
[2022-05-19 19:09:16,318] {processor.py:171} INFO - Processing /opt/airflow/dags/data_ingestion_gcs_dag.py took 0.085 seconds
[2022-05-19 19:09:46,831] {processor.py:163} INFO - Started process (PID=469) to work on /opt/airflow/dags/data_ingestion_gcs_dag.py
[2022-05-19 19:09:46,835] {processor.py:642} INFO - Processing file /opt/airflow/dags/data_ingestion_gcs_dag.py for tasks to queue
[2022-05-19 19:09:46,838] {logging_mixin.py:109} INFO - [2022-05-19 19:09:46,837] {dagbag.py:500} INFO - Filling up the DagBag from /opt/airflow/dags/data_ingestion_gcs_dag.py
[2022-05-19 19:09:46,852] {logging_mixin.py:109} INFO - [2022-05-19 19:09:46,848] {dagbag.py:334} ERROR - Failed to import: /opt/airflow/dags/data_ingestion_gcs_dag.py
Traceback (most recent call last):
  File "/home/airflow/.local/lib/python3.7/site-packages/airflow/models/dagbag.py", line 331, in _load_modules_from_file
    loader.exec_module(new_module)
  File "<frozen importlib._bootstrap_external>", line 724, in exec_module
  File "<frozen importlib._bootstrap_external>", line 860, in get_code
  File "<frozen importlib._bootstrap_external>", line 791, in source_to_code
  File "<frozen importlib._bootstrap>", line 219, in _call_with_frames_removed
  File "/opt/airflow/dags/data_ingestion_gcs_dag.py", line 1
    import os
    ^
IndentationError: unexpected indent
[2022-05-19 19:09:46,881] {processor.py:656} WARNING - No viable dags retrieved from /opt/airflow/dags/data_ingestion_gcs_dag.py
[2022-05-19 19:09:46,900] {processor.py:171} INFO - Processing /opt/airflow/dags/data_ingestion_gcs_dag.py took 0.076 seconds
[2022-05-19 19:10:17,320] {processor.py:163} INFO - Started process (PID=485) to work on /opt/airflow/dags/data_ingestion_gcs_dag.py
[2022-05-19 19:10:17,324] {processor.py:642} INFO - Processing file /opt/airflow/dags/data_ingestion_gcs_dag.py for tasks to queue
[2022-05-19 19:10:17,326] {logging_mixin.py:109} INFO - [2022-05-19 19:10:17,326] {dagbag.py:500} INFO - Filling up the DagBag from /opt/airflow/dags/data_ingestion_gcs_dag.py
[2022-05-19 19:10:17,337] {logging_mixin.py:109} INFO - [2022-05-19 19:10:17,334] {dagbag.py:334} ERROR - Failed to import: /opt/airflow/dags/data_ingestion_gcs_dag.py
Traceback (most recent call last):
  File "/home/airflow/.local/lib/python3.7/site-packages/airflow/models/dagbag.py", line 331, in _load_modules_from_file
    loader.exec_module(new_module)
  File "<frozen importlib._bootstrap_external>", line 724, in exec_module
  File "<frozen importlib._bootstrap_external>", line 860, in get_code
  File "<frozen importlib._bootstrap_external>", line 791, in source_to_code
  File "<frozen importlib._bootstrap>", line 219, in _call_with_frames_removed
  File "/opt/airflow/dags/data_ingestion_gcs_dag.py", line 1
    import os
    ^
IndentationError: unexpected indent
[2022-05-19 19:10:17,365] {processor.py:656} WARNING - No viable dags retrieved from /opt/airflow/dags/data_ingestion_gcs_dag.py
[2022-05-19 19:10:17,385] {processor.py:171} INFO - Processing /opt/airflow/dags/data_ingestion_gcs_dag.py took 0.071 seconds
[2022-05-19 19:10:48,031] {processor.py:163} INFO - Started process (PID=501) to work on /opt/airflow/dags/data_ingestion_gcs_dag.py
[2022-05-19 19:10:48,034] {processor.py:642} INFO - Processing file /opt/airflow/dags/data_ingestion_gcs_dag.py for tasks to queue
[2022-05-19 19:10:48,037] {logging_mixin.py:109} INFO - [2022-05-19 19:10:48,036] {dagbag.py:500} INFO - Filling up the DagBag from /opt/airflow/dags/data_ingestion_gcs_dag.py
[2022-05-19 19:10:48,052] {logging_mixin.py:109} INFO - [2022-05-19 19:10:48,048] {dagbag.py:334} ERROR - Failed to import: /opt/airflow/dags/data_ingestion_gcs_dag.py
Traceback (most recent call last):
  File "/home/airflow/.local/lib/python3.7/site-packages/airflow/models/dagbag.py", line 331, in _load_modules_from_file
    loader.exec_module(new_module)
  File "<frozen importlib._bootstrap_external>", line 724, in exec_module
  File "<frozen importlib._bootstrap_external>", line 860, in get_code
  File "<frozen importlib._bootstrap_external>", line 791, in source_to_code
  File "<frozen importlib._bootstrap>", line 219, in _call_with_frames_removed
  File "/opt/airflow/dags/data_ingestion_gcs_dag.py", line 1
    import os
    ^
IndentationError: unexpected indent
[2022-05-19 19:10:48,079] {processor.py:656} WARNING - No viable dags retrieved from /opt/airflow/dags/data_ingestion_gcs_dag.py
[2022-05-19 19:10:48,100] {processor.py:171} INFO - Processing /opt/airflow/dags/data_ingestion_gcs_dag.py took 0.076 seconds
[2022-05-19 19:11:18,732] {processor.py:163} INFO - Started process (PID=527) to work on /opt/airflow/dags/data_ingestion_gcs_dag.py
[2022-05-19 19:11:18,738] {processor.py:642} INFO - Processing file /opt/airflow/dags/data_ingestion_gcs_dag.py for tasks to queue
[2022-05-19 19:11:18,740] {logging_mixin.py:109} INFO - [2022-05-19 19:11:18,740] {dagbag.py:500} INFO - Filling up the DagBag from /opt/airflow/dags/data_ingestion_gcs_dag.py
[2022-05-19 19:11:18,753] {logging_mixin.py:109} INFO - [2022-05-19 19:11:18,750] {dagbag.py:334} ERROR - Failed to import: /opt/airflow/dags/data_ingestion_gcs_dag.py
Traceback (most recent call last):
  File "/home/airflow/.local/lib/python3.7/site-packages/airflow/models/dagbag.py", line 331, in _load_modules_from_file
    loader.exec_module(new_module)
  File "<frozen importlib._bootstrap_external>", line 724, in exec_module
  File "<frozen importlib._bootstrap_external>", line 860, in get_code
  File "<frozen importlib._bootstrap_external>", line 791, in source_to_code
  File "<frozen importlib._bootstrap>", line 219, in _call_with_frames_removed
  File "/opt/airflow/dags/data_ingestion_gcs_dag.py", line 1
    import os
    ^
IndentationError: unexpected indent
[2022-05-19 19:11:18,780] {processor.py:656} WARNING - No viable dags retrieved from /opt/airflow/dags/data_ingestion_gcs_dag.py
[2022-05-19 19:11:18,798] {processor.py:171} INFO - Processing /opt/airflow/dags/data_ingestion_gcs_dag.py took 0.073 seconds
[2022-05-19 19:11:49,331] {processor.py:163} INFO - Started process (PID=543) to work on /opt/airflow/dags/data_ingestion_gcs_dag.py
[2022-05-19 19:11:49,334] {processor.py:642} INFO - Processing file /opt/airflow/dags/data_ingestion_gcs_dag.py for tasks to queue
[2022-05-19 19:11:49,336] {logging_mixin.py:109} INFO - [2022-05-19 19:11:49,336] {dagbag.py:500} INFO - Filling up the DagBag from /opt/airflow/dags/data_ingestion_gcs_dag.py
[2022-05-19 19:11:49,354] {logging_mixin.py:109} INFO - [2022-05-19 19:11:49,350] {dagbag.py:334} ERROR - Failed to import: /opt/airflow/dags/data_ingestion_gcs_dag.py
Traceback (most recent call last):
  File "/home/airflow/.local/lib/python3.7/site-packages/airflow/models/dagbag.py", line 331, in _load_modules_from_file
    loader.exec_module(new_module)
  File "<frozen importlib._bootstrap_external>", line 724, in exec_module
  File "<frozen importlib._bootstrap_external>", line 860, in get_code
  File "<frozen importlib._bootstrap_external>", line 791, in source_to_code
  File "<frozen importlib._bootstrap>", line 219, in _call_with_frames_removed
  File "/opt/airflow/dags/data_ingestion_gcs_dag.py", line 1
    import os
    ^
IndentationError: unexpected indent
[2022-05-19 19:11:49,384] {processor.py:656} WARNING - No viable dags retrieved from /opt/airflow/dags/data_ingestion_gcs_dag.py
[2022-05-19 19:11:49,405] {processor.py:171} INFO - Processing /opt/airflow/dags/data_ingestion_gcs_dag.py took 0.081 seconds
[2022-05-19 19:12:19,940] {processor.py:163} INFO - Started process (PID=559) to work on /opt/airflow/dags/data_ingestion_gcs_dag.py
[2022-05-19 19:12:19,944] {processor.py:642} INFO - Processing file /opt/airflow/dags/data_ingestion_gcs_dag.py for tasks to queue
[2022-05-19 19:12:19,946] {logging_mixin.py:109} INFO - [2022-05-19 19:12:19,946] {dagbag.py:500} INFO - Filling up the DagBag from /opt/airflow/dags/data_ingestion_gcs_dag.py
[2022-05-19 19:12:19,959] {logging_mixin.py:109} INFO - [2022-05-19 19:12:19,955] {dagbag.py:334} ERROR - Failed to import: /opt/airflow/dags/data_ingestion_gcs_dag.py
Traceback (most recent call last):
  File "/home/airflow/.local/lib/python3.7/site-packages/airflow/models/dagbag.py", line 331, in _load_modules_from_file
    loader.exec_module(new_module)
  File "<frozen importlib._bootstrap_external>", line 724, in exec_module
  File "<frozen importlib._bootstrap_external>", line 860, in get_code
  File "<frozen importlib._bootstrap_external>", line 791, in source_to_code
  File "<frozen importlib._bootstrap>", line 219, in _call_with_frames_removed
  File "/opt/airflow/dags/data_ingestion_gcs_dag.py", line 1
    import os
    ^
IndentationError: unexpected indent
[2022-05-19 19:12:19,986] {processor.py:656} WARNING - No viable dags retrieved from /opt/airflow/dags/data_ingestion_gcs_dag.py
[2022-05-19 19:12:20,005] {processor.py:171} INFO - Processing /opt/airflow/dags/data_ingestion_gcs_dag.py took 0.071 seconds
[2022-05-19 19:12:50,254] {processor.py:163} INFO - Started process (PID=575) to work on /opt/airflow/dags/data_ingestion_gcs_dag.py
[2022-05-19 19:12:50,257] {processor.py:642} INFO - Processing file /opt/airflow/dags/data_ingestion_gcs_dag.py for tasks to queue
[2022-05-19 19:12:50,259] {logging_mixin.py:109} INFO - [2022-05-19 19:12:50,259] {dagbag.py:500} INFO - Filling up the DagBag from /opt/airflow/dags/data_ingestion_gcs_dag.py
[2022-05-19 19:12:50,273] {logging_mixin.py:109} INFO - [2022-05-19 19:12:50,270] {dagbag.py:334} ERROR - Failed to import: /opt/airflow/dags/data_ingestion_gcs_dag.py
Traceback (most recent call last):
  File "/home/airflow/.local/lib/python3.7/site-packages/airflow/models/dagbag.py", line 331, in _load_modules_from_file
    loader.exec_module(new_module)
  File "<frozen importlib._bootstrap_external>", line 724, in exec_module
  File "<frozen importlib._bootstrap_external>", line 860, in get_code
  File "<frozen importlib._bootstrap_external>", line 791, in source_to_code
  File "<frozen importlib._bootstrap>", line 219, in _call_with_frames_removed
  File "/opt/airflow/dags/data_ingestion_gcs_dag.py", line 1
    import os
    ^
IndentationError: unexpected indent
[2022-05-19 19:12:50,298] {processor.py:656} WARNING - No viable dags retrieved from /opt/airflow/dags/data_ingestion_gcs_dag.py
[2022-05-19 19:12:50,316] {processor.py:171} INFO - Processing /opt/airflow/dags/data_ingestion_gcs_dag.py took 0.067 seconds
[2022-05-19 19:13:20,953] {processor.py:163} INFO - Started process (PID=591) to work on /opt/airflow/dags/data_ingestion_gcs_dag.py
[2022-05-19 19:13:20,956] {processor.py:642} INFO - Processing file /opt/airflow/dags/data_ingestion_gcs_dag.py for tasks to queue
[2022-05-19 19:13:20,959] {logging_mixin.py:109} INFO - [2022-05-19 19:13:20,958] {dagbag.py:500} INFO - Filling up the DagBag from /opt/airflow/dags/data_ingestion_gcs_dag.py
[2022-05-19 19:13:20,980] {logging_mixin.py:109} INFO - [2022-05-19 19:13:20,971] {dagbag.py:334} ERROR - Failed to import: /opt/airflow/dags/data_ingestion_gcs_dag.py
Traceback (most recent call last):
  File "/home/airflow/.local/lib/python3.7/site-packages/airflow/models/dagbag.py", line 331, in _load_modules_from_file
    loader.exec_module(new_module)
  File "<frozen importlib._bootstrap_external>", line 724, in exec_module
  File "<frozen importlib._bootstrap_external>", line 860, in get_code
  File "<frozen importlib._bootstrap_external>", line 791, in source_to_code
  File "<frozen importlib._bootstrap>", line 219, in _call_with_frames_removed
  File "/opt/airflow/dags/data_ingestion_gcs_dag.py", line 1
    import os
    ^
IndentationError: unexpected indent
[2022-05-19 19:13:21,021] {processor.py:656} WARNING - No viable dags retrieved from /opt/airflow/dags/data_ingestion_gcs_dag.py
[2022-05-19 19:13:21,049] {processor.py:171} INFO - Processing /opt/airflow/dags/data_ingestion_gcs_dag.py took 0.104 seconds
[2022-05-19 19:13:51,432] {processor.py:163} INFO - Started process (PID=607) to work on /opt/airflow/dags/data_ingestion_gcs_dag.py
[2022-05-19 19:13:51,437] {processor.py:642} INFO - Processing file /opt/airflow/dags/data_ingestion_gcs_dag.py for tasks to queue
[2022-05-19 19:13:51,440] {logging_mixin.py:109} INFO - [2022-05-19 19:13:51,439] {dagbag.py:500} INFO - Filling up the DagBag from /opt/airflow/dags/data_ingestion_gcs_dag.py
[2022-05-19 19:13:51,452] {logging_mixin.py:109} INFO - [2022-05-19 19:13:51,449] {dagbag.py:334} ERROR - Failed to import: /opt/airflow/dags/data_ingestion_gcs_dag.py
Traceback (most recent call last):
  File "/home/airflow/.local/lib/python3.7/site-packages/airflow/models/dagbag.py", line 331, in _load_modules_from_file
    loader.exec_module(new_module)
  File "<frozen importlib._bootstrap_external>", line 724, in exec_module
  File "<frozen importlib._bootstrap_external>", line 860, in get_code
  File "<frozen importlib._bootstrap_external>", line 791, in source_to_code
  File "<frozen importlib._bootstrap>", line 219, in _call_with_frames_removed
  File "/opt/airflow/dags/data_ingestion_gcs_dag.py", line 1
    import os
    ^
IndentationError: unexpected indent
[2022-05-19 19:13:51,477] {processor.py:656} WARNING - No viable dags retrieved from /opt/airflow/dags/data_ingestion_gcs_dag.py
[2022-05-19 19:13:51,496] {processor.py:171} INFO - Processing /opt/airflow/dags/data_ingestion_gcs_dag.py took 0.072 seconds
[2022-05-19 19:14:22,024] {processor.py:163} INFO - Started process (PID=623) to work on /opt/airflow/dags/data_ingestion_gcs_dag.py
[2022-05-19 19:14:22,027] {processor.py:642} INFO - Processing file /opt/airflow/dags/data_ingestion_gcs_dag.py for tasks to queue
[2022-05-19 19:14:22,029] {logging_mixin.py:109} INFO - [2022-05-19 19:14:22,029] {dagbag.py:500} INFO - Filling up the DagBag from /opt/airflow/dags/data_ingestion_gcs_dag.py
[2022-05-19 19:14:22,042] {logging_mixin.py:109} INFO - [2022-05-19 19:14:22,039] {dagbag.py:334} ERROR - Failed to import: /opt/airflow/dags/data_ingestion_gcs_dag.py
Traceback (most recent call last):
  File "/home/airflow/.local/lib/python3.7/site-packages/airflow/models/dagbag.py", line 331, in _load_modules_from_file
    loader.exec_module(new_module)
  File "<frozen importlib._bootstrap_external>", line 724, in exec_module
  File "<frozen importlib._bootstrap_external>", line 860, in get_code
  File "<frozen importlib._bootstrap_external>", line 791, in source_to_code
  File "<frozen importlib._bootstrap>", line 219, in _call_with_frames_removed
  File "/opt/airflow/dags/data_ingestion_gcs_dag.py", line 1
    import os
    ^
IndentationError: unexpected indent
[2022-05-19 19:14:22,068] {processor.py:656} WARNING - No viable dags retrieved from /opt/airflow/dags/data_ingestion_gcs_dag.py
[2022-05-19 19:14:22,087] {processor.py:171} INFO - Processing /opt/airflow/dags/data_ingestion_gcs_dag.py took 0.070 seconds
[2022-05-19 19:14:52,535] {processor.py:163} INFO - Started process (PID=639) to work on /opt/airflow/dags/data_ingestion_gcs_dag.py
[2022-05-19 19:14:52,540] {processor.py:642} INFO - Processing file /opt/airflow/dags/data_ingestion_gcs_dag.py for tasks to queue
[2022-05-19 19:14:52,543] {logging_mixin.py:109} INFO - [2022-05-19 19:14:52,543] {dagbag.py:500} INFO - Filling up the DagBag from /opt/airflow/dags/data_ingestion_gcs_dag.py
[2022-05-19 19:14:52,557] {logging_mixin.py:109} INFO - [2022-05-19 19:14:52,554] {dagbag.py:334} ERROR - Failed to import: /opt/airflow/dags/data_ingestion_gcs_dag.py
Traceback (most recent call last):
  File "/home/airflow/.local/lib/python3.7/site-packages/airflow/models/dagbag.py", line 331, in _load_modules_from_file
    loader.exec_module(new_module)
  File "<frozen importlib._bootstrap_external>", line 724, in exec_module
  File "<frozen importlib._bootstrap_external>", line 860, in get_code
  File "<frozen importlib._bootstrap_external>", line 791, in source_to_code
  File "<frozen importlib._bootstrap>", line 219, in _call_with_frames_removed
  File "/opt/airflow/dags/data_ingestion_gcs_dag.py", line 1
    import os
    ^
IndentationError: unexpected indent
[2022-05-19 19:14:52,590] {processor.py:656} WARNING - No viable dags retrieved from /opt/airflow/dags/data_ingestion_gcs_dag.py
[2022-05-19 19:14:52,615] {processor.py:171} INFO - Processing /opt/airflow/dags/data_ingestion_gcs_dag.py took 0.087 seconds
[2022-05-19 19:15:23,037] {processor.py:163} INFO - Started process (PID=655) to work on /opt/airflow/dags/data_ingestion_gcs_dag.py
[2022-05-19 19:15:23,042] {processor.py:642} INFO - Processing file /opt/airflow/dags/data_ingestion_gcs_dag.py for tasks to queue
[2022-05-19 19:15:23,044] {logging_mixin.py:109} INFO - [2022-05-19 19:15:23,044] {dagbag.py:500} INFO - Filling up the DagBag from /opt/airflow/dags/data_ingestion_gcs_dag.py
[2022-05-19 19:15:23,056] {logging_mixin.py:109} INFO - [2022-05-19 19:15:23,053] {dagbag.py:334} ERROR - Failed to import: /opt/airflow/dags/data_ingestion_gcs_dag.py
Traceback (most recent call last):
  File "/home/airflow/.local/lib/python3.7/site-packages/airflow/models/dagbag.py", line 331, in _load_modules_from_file
    loader.exec_module(new_module)
  File "<frozen importlib._bootstrap_external>", line 724, in exec_module
  File "<frozen importlib._bootstrap_external>", line 860, in get_code
  File "<frozen importlib._bootstrap_external>", line 791, in source_to_code
  File "<frozen importlib._bootstrap>", line 219, in _call_with_frames_removed
  File "/opt/airflow/dags/data_ingestion_gcs_dag.py", line 1
    import os
    ^
IndentationError: unexpected indent
[2022-05-19 19:15:23,084] {processor.py:656} WARNING - No viable dags retrieved from /opt/airflow/dags/data_ingestion_gcs_dag.py
[2022-05-19 19:15:23,102] {processor.py:171} INFO - Processing /opt/airflow/dags/data_ingestion_gcs_dag.py took 0.073 seconds
[2022-05-19 19:15:53,392] {processor.py:163} INFO - Started process (PID=671) to work on /opt/airflow/dags/data_ingestion_gcs_dag.py
[2022-05-19 19:15:53,396] {processor.py:642} INFO - Processing file /opt/airflow/dags/data_ingestion_gcs_dag.py for tasks to queue
[2022-05-19 19:15:53,399] {logging_mixin.py:109} INFO - [2022-05-19 19:15:53,399] {dagbag.py:500} INFO - Filling up the DagBag from /opt/airflow/dags/data_ingestion_gcs_dag.py
[2022-05-19 19:15:53,414] {logging_mixin.py:109} INFO - [2022-05-19 19:15:53,411] {dagbag.py:334} ERROR - Failed to import: /opt/airflow/dags/data_ingestion_gcs_dag.py
Traceback (most recent call last):
  File "/home/airflow/.local/lib/python3.7/site-packages/airflow/models/dagbag.py", line 331, in _load_modules_from_file
    loader.exec_module(new_module)
  File "<frozen importlib._bootstrap_external>", line 724, in exec_module
  File "<frozen importlib._bootstrap_external>", line 860, in get_code
  File "<frozen importlib._bootstrap_external>", line 791, in source_to_code
  File "<frozen importlib._bootstrap>", line 219, in _call_with_frames_removed
  File "/opt/airflow/dags/data_ingestion_gcs_dag.py", line 1
    import os
    ^
IndentationError: unexpected indent
[2022-05-19 19:15:53,447] {processor.py:656} WARNING - No viable dags retrieved from /opt/airflow/dags/data_ingestion_gcs_dag.py
[2022-05-19 19:15:53,473] {processor.py:171} INFO - Processing /opt/airflow/dags/data_ingestion_gcs_dag.py took 0.090 seconds
[2022-05-19 19:16:24,147] {processor.py:163} INFO - Started process (PID=687) to work on /opt/airflow/dags/data_ingestion_gcs_dag.py
[2022-05-19 19:16:24,151] {processor.py:642} INFO - Processing file /opt/airflow/dags/data_ingestion_gcs_dag.py for tasks to queue
[2022-05-19 19:16:24,154] {logging_mixin.py:109} INFO - [2022-05-19 19:16:24,153] {dagbag.py:500} INFO - Filling up the DagBag from /opt/airflow/dags/data_ingestion_gcs_dag.py
[2022-05-19 19:16:24,167] {logging_mixin.py:109} INFO - [2022-05-19 19:16:24,164] {dagbag.py:334} ERROR - Failed to import: /opt/airflow/dags/data_ingestion_gcs_dag.py
Traceback (most recent call last):
  File "/home/airflow/.local/lib/python3.7/site-packages/airflow/models/dagbag.py", line 331, in _load_modules_from_file
    loader.exec_module(new_module)
  File "<frozen importlib._bootstrap_external>", line 724, in exec_module
  File "<frozen importlib._bootstrap_external>", line 860, in get_code
  File "<frozen importlib._bootstrap_external>", line 791, in source_to_code
  File "<frozen importlib._bootstrap>", line 219, in _call_with_frames_removed
  File "/opt/airflow/dags/data_ingestion_gcs_dag.py", line 1
    import os
    ^
IndentationError: unexpected indent
[2022-05-19 19:16:24,190] {processor.py:656} WARNING - No viable dags retrieved from /opt/airflow/dags/data_ingestion_gcs_dag.py
[2022-05-19 19:16:24,209] {processor.py:171} INFO - Processing /opt/airflow/dags/data_ingestion_gcs_dag.py took 0.071 seconds
[2022-05-19 19:16:54,516] {processor.py:163} INFO - Started process (PID=703) to work on /opt/airflow/dags/data_ingestion_gcs_dag.py
[2022-05-19 19:16:54,520] {processor.py:642} INFO - Processing file /opt/airflow/dags/data_ingestion_gcs_dag.py for tasks to queue
[2022-05-19 19:16:54,522] {logging_mixin.py:109} INFO - [2022-05-19 19:16:54,522] {dagbag.py:500} INFO - Filling up the DagBag from /opt/airflow/dags/data_ingestion_gcs_dag.py
[2022-05-19 19:16:54,534] {logging_mixin.py:109} INFO - [2022-05-19 19:16:54,531] {dagbag.py:334} ERROR - Failed to import: /opt/airflow/dags/data_ingestion_gcs_dag.py
Traceback (most recent call last):
  File "/home/airflow/.local/lib/python3.7/site-packages/airflow/models/dagbag.py", line 331, in _load_modules_from_file
    loader.exec_module(new_module)
  File "<frozen importlib._bootstrap_external>", line 724, in exec_module
  File "<frozen importlib._bootstrap_external>", line 860, in get_code
  File "<frozen importlib._bootstrap_external>", line 791, in source_to_code
  File "<frozen importlib._bootstrap>", line 219, in _call_with_frames_removed
  File "/opt/airflow/dags/data_ingestion_gcs_dag.py", line 1
    import os
    ^
IndentationError: unexpected indent
[2022-05-19 19:16:54,560] {processor.py:656} WARNING - No viable dags retrieved from /opt/airflow/dags/data_ingestion_gcs_dag.py
[2022-05-19 19:16:54,580] {processor.py:171} INFO - Processing /opt/airflow/dags/data_ingestion_gcs_dag.py took 0.069 seconds
[2022-05-19 19:17:25,226] {processor.py:163} INFO - Started process (PID=717) to work on /opt/airflow/dags/data_ingestion_gcs_dag.py
[2022-05-19 19:17:25,230] {processor.py:642} INFO - Processing file /opt/airflow/dags/data_ingestion_gcs_dag.py for tasks to queue
[2022-05-19 19:17:25,232] {logging_mixin.py:109} INFO - [2022-05-19 19:17:25,232] {dagbag.py:500} INFO - Filling up the DagBag from /opt/airflow/dags/data_ingestion_gcs_dag.py
[2022-05-19 19:17:25,249] {logging_mixin.py:109} INFO - [2022-05-19 19:17:25,242] {dagbag.py:334} ERROR - Failed to import: /opt/airflow/dags/data_ingestion_gcs_dag.py
Traceback (most recent call last):
  File "/home/airflow/.local/lib/python3.7/site-packages/airflow/models/dagbag.py", line 331, in _load_modules_from_file
    loader.exec_module(new_module)
  File "<frozen importlib._bootstrap_external>", line 724, in exec_module
  File "<frozen importlib._bootstrap_external>", line 860, in get_code
  File "<frozen importlib._bootstrap_external>", line 791, in source_to_code
  File "<frozen importlib._bootstrap>", line 219, in _call_with_frames_removed
  File "/opt/airflow/dags/data_ingestion_gcs_dag.py", line 1
    import os
    ^
IndentationError: unexpected indent
[2022-05-19 19:17:25,283] {processor.py:656} WARNING - No viable dags retrieved from /opt/airflow/dags/data_ingestion_gcs_dag.py
[2022-05-19 19:17:25,305] {processor.py:171} INFO - Processing /opt/airflow/dags/data_ingestion_gcs_dag.py took 0.086 seconds
[2022-05-19 19:17:55,827] {processor.py:163} INFO - Started process (PID=725) to work on /opt/airflow/dags/data_ingestion_gcs_dag.py
[2022-05-19 19:17:55,831] {processor.py:642} INFO - Processing file /opt/airflow/dags/data_ingestion_gcs_dag.py for tasks to queue
[2022-05-19 19:17:55,833] {logging_mixin.py:109} INFO - [2022-05-19 19:17:55,833] {dagbag.py:500} INFO - Filling up the DagBag from /opt/airflow/dags/data_ingestion_gcs_dag.py
[2022-05-19 19:17:55,843] {logging_mixin.py:109} INFO - [2022-05-19 19:17:55,840] {dagbag.py:334} ERROR - Failed to import: /opt/airflow/dags/data_ingestion_gcs_dag.py
Traceback (most recent call last):
  File "/home/airflow/.local/lib/python3.7/site-packages/airflow/models/dagbag.py", line 331, in _load_modules_from_file
    loader.exec_module(new_module)
  File "<frozen importlib._bootstrap_external>", line 724, in exec_module
  File "<frozen importlib._bootstrap_external>", line 860, in get_code
  File "<frozen importlib._bootstrap_external>", line 791, in source_to_code
  File "<frozen importlib._bootstrap>", line 219, in _call_with_frames_removed
  File "/opt/airflow/dags/data_ingestion_gcs_dag.py", line 1
    import os
    ^
IndentationError: unexpected indent
[2022-05-19 19:17:55,871] {processor.py:656} WARNING - No viable dags retrieved from /opt/airflow/dags/data_ingestion_gcs_dag.py
[2022-05-19 19:17:55,890] {processor.py:171} INFO - Processing /opt/airflow/dags/data_ingestion_gcs_dag.py took 0.069 seconds
[2022-05-19 19:18:26,039] {processor.py:163} INFO - Started process (PID=741) to work on /opt/airflow/dags/data_ingestion_gcs_dag.py
[2022-05-19 19:18:26,044] {processor.py:642} INFO - Processing file /opt/airflow/dags/data_ingestion_gcs_dag.py for tasks to queue
[2022-05-19 19:18:26,046] {logging_mixin.py:109} INFO - [2022-05-19 19:18:26,046] {dagbag.py:500} INFO - Filling up the DagBag from /opt/airflow/dags/data_ingestion_gcs_dag.py
[2022-05-19 19:18:26,060] {logging_mixin.py:109} INFO - [2022-05-19 19:18:26,057] {dagbag.py:334} ERROR - Failed to import: /opt/airflow/dags/data_ingestion_gcs_dag.py
Traceback (most recent call last):
  File "/home/airflow/.local/lib/python3.7/site-packages/airflow/models/dagbag.py", line 331, in _load_modules_from_file
    loader.exec_module(new_module)
  File "<frozen importlib._bootstrap_external>", line 724, in exec_module
  File "<frozen importlib._bootstrap_external>", line 860, in get_code
  File "<frozen importlib._bootstrap_external>", line 791, in source_to_code
  File "<frozen importlib._bootstrap>", line 219, in _call_with_frames_removed
  File "/opt/airflow/dags/data_ingestion_gcs_dag.py", line 1
    import os
    ^
IndentationError: unexpected indent
[2022-05-19 19:18:26,096] {processor.py:656} WARNING - No viable dags retrieved from /opt/airflow/dags/data_ingestion_gcs_dag.py
[2022-05-19 19:18:26,116] {processor.py:171} INFO - Processing /opt/airflow/dags/data_ingestion_gcs_dag.py took 0.085 seconds
[2022-05-19 19:18:56,735] {processor.py:163} INFO - Started process (PID=757) to work on /opt/airflow/dags/data_ingestion_gcs_dag.py
[2022-05-19 19:18:56,739] {processor.py:642} INFO - Processing file /opt/airflow/dags/data_ingestion_gcs_dag.py for tasks to queue
[2022-05-19 19:18:56,742] {logging_mixin.py:109} INFO - [2022-05-19 19:18:56,742] {dagbag.py:500} INFO - Filling up the DagBag from /opt/airflow/dags/data_ingestion_gcs_dag.py
[2022-05-19 19:18:56,755] {logging_mixin.py:109} INFO - [2022-05-19 19:18:56,752] {dagbag.py:334} ERROR - Failed to import: /opt/airflow/dags/data_ingestion_gcs_dag.py
Traceback (most recent call last):
  File "/home/airflow/.local/lib/python3.7/site-packages/airflow/models/dagbag.py", line 331, in _load_modules_from_file
    loader.exec_module(new_module)
  File "<frozen importlib._bootstrap_external>", line 724, in exec_module
  File "<frozen importlib._bootstrap_external>", line 860, in get_code
  File "<frozen importlib._bootstrap_external>", line 791, in source_to_code
  File "<frozen importlib._bootstrap>", line 219, in _call_with_frames_removed
  File "/opt/airflow/dags/data_ingestion_gcs_dag.py", line 1
    import os
    ^
IndentationError: unexpected indent
[2022-05-19 19:18:56,781] {processor.py:656} WARNING - No viable dags retrieved from /opt/airflow/dags/data_ingestion_gcs_dag.py
[2022-05-19 19:18:56,799] {processor.py:171} INFO - Processing /opt/airflow/dags/data_ingestion_gcs_dag.py took 0.073 seconds
[2022-05-19 19:19:27,031] {processor.py:163} INFO - Started process (PID=773) to work on /opt/airflow/dags/data_ingestion_gcs_dag.py
[2022-05-19 19:19:27,035] {processor.py:642} INFO - Processing file /opt/airflow/dags/data_ingestion_gcs_dag.py for tasks to queue
[2022-05-19 19:19:27,037] {logging_mixin.py:109} INFO - [2022-05-19 19:19:27,037] {dagbag.py:500} INFO - Filling up the DagBag from /opt/airflow/dags/data_ingestion_gcs_dag.py
[2022-05-19 19:19:27,051] {logging_mixin.py:109} INFO - [2022-05-19 19:19:27,047] {dagbag.py:334} ERROR - Failed to import: /opt/airflow/dags/data_ingestion_gcs_dag.py
Traceback (most recent call last):
  File "/home/airflow/.local/lib/python3.7/site-packages/airflow/models/dagbag.py", line 331, in _load_modules_from_file
    loader.exec_module(new_module)
  File "<frozen importlib._bootstrap_external>", line 724, in exec_module
  File "<frozen importlib._bootstrap_external>", line 860, in get_code
  File "<frozen importlib._bootstrap_external>", line 791, in source_to_code
  File "<frozen importlib._bootstrap>", line 219, in _call_with_frames_removed
  File "/opt/airflow/dags/data_ingestion_gcs_dag.py", line 1
    import os
    ^
IndentationError: unexpected indent
[2022-05-19 19:19:27,081] {processor.py:656} WARNING - No viable dags retrieved from /opt/airflow/dags/data_ingestion_gcs_dag.py
[2022-05-19 19:19:27,103] {processor.py:171} INFO - Processing /opt/airflow/dags/data_ingestion_gcs_dag.py took 0.080 seconds
[2022-05-19 19:19:57,662] {processor.py:163} INFO - Started process (PID=789) to work on /opt/airflow/dags/data_ingestion_gcs_dag.py
[2022-05-19 19:19:57,667] {processor.py:642} INFO - Processing file /opt/airflow/dags/data_ingestion_gcs_dag.py for tasks to queue
[2022-05-19 19:19:57,669] {logging_mixin.py:109} INFO - [2022-05-19 19:19:57,669] {dagbag.py:500} INFO - Filling up the DagBag from /opt/airflow/dags/data_ingestion_gcs_dag.py
[2022-05-19 19:19:57,683] {logging_mixin.py:109} INFO - [2022-05-19 19:19:57,680] {dagbag.py:334} ERROR - Failed to import: /opt/airflow/dags/data_ingestion_gcs_dag.py
Traceback (most recent call last):
  File "/home/airflow/.local/lib/python3.7/site-packages/airflow/models/dagbag.py", line 331, in _load_modules_from_file
    loader.exec_module(new_module)
  File "<frozen importlib._bootstrap_external>", line 724, in exec_module
  File "<frozen importlib._bootstrap_external>", line 860, in get_code
  File "<frozen importlib._bootstrap_external>", line 791, in source_to_code
  File "<frozen importlib._bootstrap>", line 219, in _call_with_frames_removed
  File "/opt/airflow/dags/data_ingestion_gcs_dag.py", line 1
    import os
    ^
IndentationError: unexpected indent
[2022-05-19 19:19:57,709] {processor.py:656} WARNING - No viable dags retrieved from /opt/airflow/dags/data_ingestion_gcs_dag.py
[2022-05-19 19:19:57,727] {processor.py:171} INFO - Processing /opt/airflow/dags/data_ingestion_gcs_dag.py took 0.073 seconds
[2022-05-19 19:20:27,907] {processor.py:163} INFO - Started process (PID=805) to work on /opt/airflow/dags/data_ingestion_gcs_dag.py
[2022-05-19 19:20:27,911] {processor.py:642} INFO - Processing file /opt/airflow/dags/data_ingestion_gcs_dag.py for tasks to queue
[2022-05-19 19:20:27,914] {logging_mixin.py:109} INFO - [2022-05-19 19:20:27,913] {dagbag.py:500} INFO - Filling up the DagBag from /opt/airflow/dags/data_ingestion_gcs_dag.py
[2022-05-19 19:20:27,927] {logging_mixin.py:109} INFO - [2022-05-19 19:20:27,924] {dagbag.py:334} ERROR - Failed to import: /opt/airflow/dags/data_ingestion_gcs_dag.py
Traceback (most recent call last):
  File "/home/airflow/.local/lib/python3.7/site-packages/airflow/models/dagbag.py", line 331, in _load_modules_from_file
    loader.exec_module(new_module)
  File "<frozen importlib._bootstrap_external>", line 724, in exec_module
  File "<frozen importlib._bootstrap_external>", line 860, in get_code
  File "<frozen importlib._bootstrap_external>", line 791, in source_to_code
  File "<frozen importlib._bootstrap>", line 219, in _call_with_frames_removed
  File "/opt/airflow/dags/data_ingestion_gcs_dag.py", line 1
    import os
    ^
IndentationError: unexpected indent
[2022-05-19 19:20:27,957] {processor.py:656} WARNING - No viable dags retrieved from /opt/airflow/dags/data_ingestion_gcs_dag.py
[2022-05-19 19:20:27,978] {processor.py:171} INFO - Processing /opt/airflow/dags/data_ingestion_gcs_dag.py took 0.078 seconds
[2022-05-19 19:20:58,571] {processor.py:163} INFO - Started process (PID=821) to work on /opt/airflow/dags/data_ingestion_gcs_dag.py
[2022-05-19 19:20:58,575] {processor.py:642} INFO - Processing file /opt/airflow/dags/data_ingestion_gcs_dag.py for tasks to queue
[2022-05-19 19:20:58,578] {logging_mixin.py:109} INFO - [2022-05-19 19:20:58,577] {dagbag.py:500} INFO - Filling up the DagBag from /opt/airflow/dags/data_ingestion_gcs_dag.py
[2022-05-19 19:20:58,592] {logging_mixin.py:109} INFO - [2022-05-19 19:20:58,589] {dagbag.py:334} ERROR - Failed to import: /opt/airflow/dags/data_ingestion_gcs_dag.py
Traceback (most recent call last):
  File "/home/airflow/.local/lib/python3.7/site-packages/airflow/models/dagbag.py", line 331, in _load_modules_from_file
    loader.exec_module(new_module)
  File "<frozen importlib._bootstrap_external>", line 724, in exec_module
  File "<frozen importlib._bootstrap_external>", line 860, in get_code
  File "<frozen importlib._bootstrap_external>", line 791, in source_to_code
  File "<frozen importlib._bootstrap>", line 219, in _call_with_frames_removed
  File "/opt/airflow/dags/data_ingestion_gcs_dag.py", line 1
    import os
    ^
IndentationError: unexpected indent
[2022-05-19 19:20:58,630] {processor.py:656} WARNING - No viable dags retrieved from /opt/airflow/dags/data_ingestion_gcs_dag.py
[2022-05-19 19:20:58,650] {processor.py:171} INFO - Processing /opt/airflow/dags/data_ingestion_gcs_dag.py took 0.091 seconds
[2022-05-19 19:21:29,216] {processor.py:163} INFO - Started process (PID=837) to work on /opt/airflow/dags/data_ingestion_gcs_dag.py
[2022-05-19 19:21:29,221] {processor.py:642} INFO - Processing file /opt/airflow/dags/data_ingestion_gcs_dag.py for tasks to queue
[2022-05-19 19:21:29,224] {logging_mixin.py:109} INFO - [2022-05-19 19:21:29,223] {dagbag.py:500} INFO - Filling up the DagBag from /opt/airflow/dags/data_ingestion_gcs_dag.py
[2022-05-19 19:21:29,239] {logging_mixin.py:109} INFO - [2022-05-19 19:21:29,235] {dagbag.py:334} ERROR - Failed to import: /opt/airflow/dags/data_ingestion_gcs_dag.py
Traceback (most recent call last):
  File "/home/airflow/.local/lib/python3.7/site-packages/airflow/models/dagbag.py", line 331, in _load_modules_from_file
    loader.exec_module(new_module)
  File "<frozen importlib._bootstrap_external>", line 724, in exec_module
  File "<frozen importlib._bootstrap_external>", line 860, in get_code
  File "<frozen importlib._bootstrap_external>", line 791, in source_to_code
  File "<frozen importlib._bootstrap>", line 219, in _call_with_frames_removed
  File "/opt/airflow/dags/data_ingestion_gcs_dag.py", line 1
    import os
    ^
IndentationError: unexpected indent
[2022-05-19 19:21:29,268] {processor.py:656} WARNING - No viable dags retrieved from /opt/airflow/dags/data_ingestion_gcs_dag.py
[2022-05-19 19:21:29,289] {processor.py:171} INFO - Processing /opt/airflow/dags/data_ingestion_gcs_dag.py took 0.082 seconds
[2022-05-19 19:21:59,793] {processor.py:163} INFO - Started process (PID=853) to work on /opt/airflow/dags/data_ingestion_gcs_dag.py
[2022-05-19 19:21:59,796] {processor.py:642} INFO - Processing file /opt/airflow/dags/data_ingestion_gcs_dag.py for tasks to queue
[2022-05-19 19:21:59,798] {logging_mixin.py:109} INFO - [2022-05-19 19:21:59,798] {dagbag.py:500} INFO - Filling up the DagBag from /opt/airflow/dags/data_ingestion_gcs_dag.py
[2022-05-19 19:21:59,810] {logging_mixin.py:109} INFO - [2022-05-19 19:21:59,807] {dagbag.py:334} ERROR - Failed to import: /opt/airflow/dags/data_ingestion_gcs_dag.py
Traceback (most recent call last):
  File "/home/airflow/.local/lib/python3.7/site-packages/airflow/models/dagbag.py", line 331, in _load_modules_from_file
    loader.exec_module(new_module)
  File "<frozen importlib._bootstrap_external>", line 724, in exec_module
  File "<frozen importlib._bootstrap_external>", line 860, in get_code
  File "<frozen importlib._bootstrap_external>", line 791, in source_to_code
  File "<frozen importlib._bootstrap>", line 219, in _call_with_frames_removed
  File "/opt/airflow/dags/data_ingestion_gcs_dag.py", line 1
    import os
    ^
IndentationError: unexpected indent
[2022-05-19 19:21:59,835] {processor.py:656} WARNING - No viable dags retrieved from /opt/airflow/dags/data_ingestion_gcs_dag.py
[2022-05-19 19:21:59,854] {processor.py:171} INFO - Processing /opt/airflow/dags/data_ingestion_gcs_dag.py took 0.067 seconds
[2022-05-19 19:22:10,004] {processor.py:163} INFO - Started process (PID=859) to work on /opt/airflow/dags/data_ingestion_gcs_dag.py
[2022-05-19 19:22:10,008] {processor.py:642} INFO - Processing file /opt/airflow/dags/data_ingestion_gcs_dag.py for tasks to queue
[2022-05-19 19:22:10,010] {logging_mixin.py:109} INFO - [2022-05-19 19:22:10,010] {dagbag.py:500} INFO - Filling up the DagBag from /opt/airflow/dags/data_ingestion_gcs_dag.py
[2022-05-19 19:22:13,083] {processor.py:654} INFO - DAG(s) dict_keys(['data_ingestion_gcs_dag']) retrieved from /opt/airflow/dags/data_ingestion_gcs_dag.py
[2022-05-19 19:22:17,654] {logging_mixin.py:109} INFO - [2022-05-19 19:22:17,653] {manager.py:496} INFO - Created Permission View: can edit on DAG:data_ingestion_gcs_dag
[2022-05-19 19:22:17,678] {logging_mixin.py:109} INFO - [2022-05-19 19:22:17,678] {manager.py:496} INFO - Created Permission View: can read on DAG:data_ingestion_gcs_dag
[2022-05-19 19:22:17,680] {logging_mixin.py:109} INFO - [2022-05-19 19:22:17,679] {dag.py:2396} INFO - Sync 1 DAGs
[2022-05-19 19:22:17,709] {logging_mixin.py:109} INFO - [2022-05-19 19:22:17,708] {dag.py:2415} INFO - Creating ORM DAG for data_ingestion_gcs_dag
[2022-05-19 19:22:17,749] {logging_mixin.py:109} INFO - [2022-05-19 19:22:17,748] {dag.py:2935} INFO - Setting next_dagrun for data_ingestion_gcs_dag to 2022-05-18 00:00:00+00:00
[2022-05-19 19:22:17,790] {processor.py:171} INFO - Processing /opt/airflow/dags/data_ingestion_gcs_dag.py took 7.792 seconds
[2022-05-19 19:22:18,868] {processor.py:163} INFO - Started process (PID=877) to work on /opt/airflow/dags/data_ingestion_gcs_dag.py
[2022-05-19 19:22:18,874] {processor.py:642} INFO - Processing file /opt/airflow/dags/data_ingestion_gcs_dag.py for tasks to queue
[2022-05-19 19:22:18,877] {logging_mixin.py:109} INFO - [2022-05-19 19:22:18,876] {dagbag.py:500} INFO - Filling up the DagBag from /opt/airflow/dags/data_ingestion_gcs_dag.py
[2022-05-19 19:22:21,520] {processor.py:654} INFO - DAG(s) dict_keys(['data_ingestion_gcs_dag']) retrieved from /opt/airflow/dags/data_ingestion_gcs_dag.py
[2022-05-19 19:22:21,530] {logging_mixin.py:109} INFO - [2022-05-19 19:22:21,529] {dag.py:2396} INFO - Sync 1 DAGs
[2022-05-19 19:22:21,580] {logging_mixin.py:109} INFO - [2022-05-19 19:22:21,580] {dag.py:2935} INFO - Setting next_dagrun for data_ingestion_gcs_dag to 2022-05-18 00:00:00+00:00
[2022-05-19 19:22:21,605] {processor.py:171} INFO - Processing /opt/airflow/dags/data_ingestion_gcs_dag.py took 2.746 seconds
[2022-05-19 19:22:52,003] {processor.py:163} INFO - Started process (PID=897) to work on /opt/airflow/dags/data_ingestion_gcs_dag.py
[2022-05-19 19:22:52,009] {processor.py:642} INFO - Processing file /opt/airflow/dags/data_ingestion_gcs_dag.py for tasks to queue
[2022-05-19 19:22:52,011] {logging_mixin.py:109} INFO - [2022-05-19 19:22:52,011] {dagbag.py:500} INFO - Filling up the DagBag from /opt/airflow/dags/data_ingestion_gcs_dag.py
[2022-05-19 19:22:54,894] {processor.py:654} INFO - DAG(s) dict_keys(['data_ingestion_gcs_dag']) retrieved from /opt/airflow/dags/data_ingestion_gcs_dag.py
[2022-05-19 19:22:54,930] {logging_mixin.py:109} INFO - [2022-05-19 19:22:54,929] {dag.py:2396} INFO - Sync 1 DAGs
[2022-05-19 19:22:54,986] {logging_mixin.py:109} INFO - [2022-05-19 19:22:54,986] {dag.py:2935} INFO - Setting next_dagrun for data_ingestion_gcs_dag to 2022-05-18 00:00:00+00:00
[2022-05-19 19:22:55,010] {processor.py:171} INFO - Processing /opt/airflow/dags/data_ingestion_gcs_dag.py took 3.013 seconds
[2022-05-19 19:23:25,385] {processor.py:163} INFO - Started process (PID=919) to work on /opt/airflow/dags/data_ingestion_gcs_dag.py
[2022-05-19 19:23:25,389] {processor.py:642} INFO - Processing file /opt/airflow/dags/data_ingestion_gcs_dag.py for tasks to queue
[2022-05-19 19:23:25,391] {logging_mixin.py:109} INFO - [2022-05-19 19:23:25,391] {dagbag.py:500} INFO - Filling up the DagBag from /opt/airflow/dags/data_ingestion_gcs_dag.py
[2022-05-19 19:23:28,040] {processor.py:654} INFO - DAG(s) dict_keys(['data_ingestion_gcs_dag']) retrieved from /opt/airflow/dags/data_ingestion_gcs_dag.py
[2022-05-19 19:23:28,070] {logging_mixin.py:109} INFO - [2022-05-19 19:23:28,069] {dag.py:2396} INFO - Sync 1 DAGs
[2022-05-19 19:23:28,122] {logging_mixin.py:109} INFO - [2022-05-19 19:23:28,122] {dag.py:2935} INFO - Setting next_dagrun for data_ingestion_gcs_dag to 2022-05-18 00:00:00+00:00
[2022-05-19 19:23:28,143] {processor.py:171} INFO - Processing /opt/airflow/dags/data_ingestion_gcs_dag.py took 2.763 seconds
[2022-05-19 19:23:58,561] {processor.py:163} INFO - Started process (PID=939) to work on /opt/airflow/dags/data_ingestion_gcs_dag.py
[2022-05-19 19:23:58,565] {processor.py:642} INFO - Processing file /opt/airflow/dags/data_ingestion_gcs_dag.py for tasks to queue
[2022-05-19 19:23:58,567] {logging_mixin.py:109} INFO - [2022-05-19 19:23:58,566] {dagbag.py:500} INFO - Filling up the DagBag from /opt/airflow/dags/data_ingestion_gcs_dag.py
[2022-05-19 19:24:01,394] {processor.py:654} INFO - DAG(s) dict_keys(['data_ingestion_gcs_dag']) retrieved from /opt/airflow/dags/data_ingestion_gcs_dag.py
[2022-05-19 19:24:01,430] {logging_mixin.py:109} INFO - [2022-05-19 19:24:01,429] {dag.py:2396} INFO - Sync 1 DAGs
[2022-05-19 19:24:01,490] {logging_mixin.py:109} INFO - [2022-05-19 19:24:01,489] {dag.py:2935} INFO - Setting next_dagrun for data_ingestion_gcs_dag to 2022-05-18 00:00:00+00:00
[2022-05-19 19:24:01,515] {processor.py:171} INFO - Processing /opt/airflow/dags/data_ingestion_gcs_dag.py took 2.960 seconds
[2022-05-19 19:24:31,727] {processor.py:163} INFO - Started process (PID=959) to work on /opt/airflow/dags/data_ingestion_gcs_dag.py
[2022-05-19 19:24:31,732] {processor.py:642} INFO - Processing file /opt/airflow/dags/data_ingestion_gcs_dag.py for tasks to queue
[2022-05-19 19:24:31,735] {logging_mixin.py:109} INFO - [2022-05-19 19:24:31,734] {dagbag.py:500} INFO - Filling up the DagBag from /opt/airflow/dags/data_ingestion_gcs_dag.py
[2022-05-19 19:24:34,327] {processor.py:654} INFO - DAG(s) dict_keys(['data_ingestion_gcs_dag']) retrieved from /opt/airflow/dags/data_ingestion_gcs_dag.py
[2022-05-19 19:24:34,358] {logging_mixin.py:109} INFO - [2022-05-19 19:24:34,357] {dag.py:2396} INFO - Sync 1 DAGs
[2022-05-19 19:24:34,409] {logging_mixin.py:109} INFO - [2022-05-19 19:24:34,408] {dag.py:2935} INFO - Setting next_dagrun for data_ingestion_gcs_dag to 2022-05-18 00:00:00+00:00
[2022-05-19 19:24:34,430] {processor.py:171} INFO - Processing /opt/airflow/dags/data_ingestion_gcs_dag.py took 2.713 seconds
[2022-05-19 19:25:04,688] {processor.py:163} INFO - Started process (PID=979) to work on /opt/airflow/dags/data_ingestion_gcs_dag.py
[2022-05-19 19:25:04,696] {processor.py:642} INFO - Processing file /opt/airflow/dags/data_ingestion_gcs_dag.py for tasks to queue
[2022-05-19 19:25:04,700] {logging_mixin.py:109} INFO - [2022-05-19 19:25:04,699] {dagbag.py:500} INFO - Filling up the DagBag from /opt/airflow/dags/data_ingestion_gcs_dag.py
[2022-05-19 19:25:07,559] {processor.py:654} INFO - DAG(s) dict_keys(['data_ingestion_gcs_dag']) retrieved from /opt/airflow/dags/data_ingestion_gcs_dag.py
[2022-05-19 19:25:07,595] {logging_mixin.py:109} INFO - [2022-05-19 19:25:07,594] {dag.py:2396} INFO - Sync 1 DAGs
[2022-05-19 19:25:07,660] {logging_mixin.py:109} INFO - [2022-05-19 19:25:07,659] {dag.py:2935} INFO - Setting next_dagrun for data_ingestion_gcs_dag to 2022-05-18 00:00:00+00:00
[2022-05-19 19:25:07,686] {processor.py:171} INFO - Processing /opt/airflow/dags/data_ingestion_gcs_dag.py took 3.008 seconds
[2022-05-19 19:25:38,187] {processor.py:163} INFO - Started process (PID=999) to work on /opt/airflow/dags/data_ingestion_gcs_dag.py
[2022-05-19 19:25:38,192] {processor.py:642} INFO - Processing file /opt/airflow/dags/data_ingestion_gcs_dag.py for tasks to queue
[2022-05-19 19:25:38,194] {logging_mixin.py:109} INFO - [2022-05-19 19:25:38,194] {dagbag.py:500} INFO - Filling up the DagBag from /opt/airflow/dags/data_ingestion_gcs_dag.py
[2022-05-19 19:25:40,757] {processor.py:654} INFO - DAG(s) dict_keys(['data_ingestion_gcs_dag']) retrieved from /opt/airflow/dags/data_ingestion_gcs_dag.py
[2022-05-19 19:25:40,788] {logging_mixin.py:109} INFO - [2022-05-19 19:25:40,787] {dag.py:2396} INFO - Sync 1 DAGs
[2022-05-19 19:25:40,839] {logging_mixin.py:109} INFO - [2022-05-19 19:25:40,839] {dag.py:2935} INFO - Setting next_dagrun for data_ingestion_gcs_dag to 2022-05-18 00:00:00+00:00
[2022-05-19 19:25:40,860] {processor.py:171} INFO - Processing /opt/airflow/dags/data_ingestion_gcs_dag.py took 2.680 seconds
[2022-05-19 19:26:11,405] {processor.py:163} INFO - Started process (PID=1019) to work on /opt/airflow/dags/data_ingestion_gcs_dag.py
[2022-05-19 19:26:11,409] {processor.py:642} INFO - Processing file /opt/airflow/dags/data_ingestion_gcs_dag.py for tasks to queue
[2022-05-19 19:26:11,411] {logging_mixin.py:109} INFO - [2022-05-19 19:26:11,411] {dagbag.py:500} INFO - Filling up the DagBag from /opt/airflow/dags/data_ingestion_gcs_dag.py
[2022-05-19 19:26:14,484] {processor.py:654} INFO - DAG(s) dict_keys(['data_ingestion_gcs_dag']) retrieved from /opt/airflow/dags/data_ingestion_gcs_dag.py
[2022-05-19 19:26:14,524] {logging_mixin.py:109} INFO - [2022-05-19 19:26:14,523] {dag.py:2396} INFO - Sync 1 DAGs
[2022-05-19 19:26:14,578] {logging_mixin.py:109} INFO - [2022-05-19 19:26:14,577] {dag.py:2935} INFO - Setting next_dagrun for data_ingestion_gcs_dag to 2022-05-18 00:00:00+00:00
[2022-05-19 19:26:14,605] {processor.py:171} INFO - Processing /opt/airflow/dags/data_ingestion_gcs_dag.py took 3.208 seconds
[2022-05-19 19:26:44,985] {processor.py:163} INFO - Started process (PID=1082) to work on /opt/airflow/dags/data_ingestion_gcs_dag.py
[2022-05-19 19:26:44,988] {processor.py:642} INFO - Processing file /opt/airflow/dags/data_ingestion_gcs_dag.py for tasks to queue
[2022-05-19 19:26:44,990] {logging_mixin.py:109} INFO - [2022-05-19 19:26:44,990] {dagbag.py:500} INFO - Filling up the DagBag from /opt/airflow/dags/data_ingestion_gcs_dag.py
[2022-05-19 19:26:47,919] {processor.py:654} INFO - DAG(s) dict_keys(['data_ingestion_gcs_dag']) retrieved from /opt/airflow/dags/data_ingestion_gcs_dag.py
[2022-05-19 19:26:47,954] {logging_mixin.py:109} INFO - [2022-05-19 19:26:47,953] {dag.py:2396} INFO - Sync 1 DAGs
[2022-05-19 19:26:48,029] {processor.py:171} INFO - Processing /opt/airflow/dags/data_ingestion_gcs_dag.py took 3.051 seconds
